Workbook

Sheet Dataset
A1: Segment | B1: Country | C1: Product | D1: Discount Band | E1: Units Sold | F1: Manufacturing Price | G1: Sale Price | H1: Gross Sales | I1: Discounts | J1: Sales | K1: COGS | L1: Profit | M1: Date | N1: Month Number | O1: Month Name | P1: Year
A2: Government | B2: Canada | C2: Carretera | D2: None | E2: 1618.5 | F2: 3 | G2: 20 | H2: 32370 | I2: 0 | J2: 32370 | K2: 16185 | L2: 16185 | M2: 41640 | N2: 1 | O2: January | P2: 2014
A3: Government | B3: Germany | C3: Carretera | D3: None | E3: 1321 | F3: 3 | G3: 20 | H3: 26420 | I3: 0 | J3: 26420 | K3: 13210 | L3: 13210 | M3: 41640 | N3: 1 | O3: January | P3: 2014
A4: Midmarket | B4: France | C4: Carretera | D4: None | E4: 2178 | F4: 3 | G4: 15 | H4: 32670 | I4: 0 | J4: 32670 | K4: 21780 | L4: 10890 | M4: 41791 | N4: 6 | O4: June | P4: 2014
A5: Midmarket | B5: Germany | C5: Carretera | D5: None | E5: 888 | F5: 3 | G5: 15 | H5: 13320 | I5: 0 | J5: 13320 | K5: 8880 | L5: 4440 | M5: 41791 | N5: 6 | O5: June | P5: 2014
A6: Midmarket | B6: Mexico | C6: Carretera | D6: None | E6: 2470 | F6: 3 | G6: 15 | H6: 37050 | I6: 0 | J6: 37050 | K6: 24700 | L6: 12350 | M6: 41791 | N6: 6 | O6: June | P6: 2014
A7: Government | B7: Germany | C7: Carretera | D7: None | E7: 1513 | F7: 3 | G7: 350 | H7: 529550 | I7: 0 | J7: 529550 | K7: 393380 | L7: 136170 | M7: 41974 | N7: 12 | O7: December | P7: 2014
A8: Midmarket | B8: Germany | C8: Montana | D8: None | E8: 921 | F8: 5 | G8: 15 | H8: 13815 | I8: 0 | J8: 13815 | K8: 9210 | L8: 4605 | M8: 41699 | N8: 3 | O8: March | P8: 2014
A9: Channel Partners | B9: Canada | C9: Montana | D9: None | E9: 2518 | F9: 5 | G9: 12 | H9: 30216 | I9: 0 | J9: 30216 | K9: 7554 | L9: 22662 | M9: 41791 | N9: 6 | O9: June | P9: 2014
A10: Government | B10: France | C10: Montana | D10: None | E10: 1899 | F10: 5 | G10: 20 | H10: 37980 | I10: 0 | J10: 37980 | K10: 18990 | L10: 18990 | M10: 41791 | N10: 6 | O10: June | P10: 2014
A11: Channel Partners | B11: Germany | C11: Montana | D11: None | E11: 1545 | F11: 5 | G11: 12 | H11: 18540 | I11: 0 | J11: 18540 | K11: 4635 | L11: 13905 | M11: 41791 | N11: 6 | O11: June | P11: 2014
A12: Midmarket | B12: Mexico | C12: Montana | D12: None | E12: 2470 | F12: 5 | G12: 15 | H12: 37050 | I12: 0 | J12: 37050 | K12: 24700 | L12: 12350 | M12: 41791 | N12: 6 | O12: June | P12: 2014
A13: Enterprise | B13: Canada | C13: Montana | D13: None | E13: 2665.5 | F13: 5 | G13: 125 | H13: 333187.5 | I13: 0 | J13: 333187.5 | K13: 319860 | L13: 13327.5 | M13: 41821 | N13: 7 | O13: July | P13: 2014
... A701: Channel Partners | B701: United States of America | C701: VTT | D701: High | E701: 1806 | F701: 250 | G701: 12 | H701: 21672 | I701: 3250.8 | J701: 18421.2 | K701: 5418 | L701: 13003.2 | M701: 41760 | N701: 5 | O701: May | P701: 2014

Sheet Statistical Analysis
F1: Statistical Analysis
F2: 1. Descriptive Statistics | M2: 2. Correlation Analysis
E3: Numerical Data column name | F3: Average | G3: Median | H3: Minimum | I3: Maximum | J3: Std Dev
E4: Units Sold | F4: =AVERAGE(Dataset!E:E) -> 1608.2943 | G4: =MEDIAN(Dataset!E:E) -> 1542.5 | H4: =MIN(Dataset!E:E) -> 200 | I4: =MAX(Dataset!E:E) -> 4492.5 | J4: =_xlfn.STDEV.P(Dataset!E:E) -> 866.80805 | M4: Correlation Sales vs Profits | N4: =CORREL(Dataset!J:J,Dataset!L:L) -> 0.80546219
E5: Manufacturing Price | F5: =AVERAGE(Dataset!F:F) -> 96.477143 | G5: =MEDIAN(Dataset!F:F) -> 10 | H5: =MIN(Dataset!F:F) -> 3 | I5: =MAX(Dataset!F:F) -> 260 | J5: =_xlfn.STDEV.P(Dataset!F:F) -> 108.52501 | M5: Correlation Units vs Profit | N5: =CORREL(Dataset!E:E,Dataset!L:L) -> 0.22843691
E6: Sales Price | F6: =AVERAGE(Dataset!G:G) -> 118.42857 | G6: =MEDIAN(Dataset!G:G) -> 20 | H6: =MIN(Dataset!G:G) -> 7 | I6: =MAX(Dataset!G:G) -> 350 | J6: =_xlfn.STDEV.P(Dataset!G:G) -> 136.67778 | M6: Correlation Units vs Sales | N6: =CORREL(Dataset!E:E,Dataset!J:J) -> 0.32691397
E7: Gross Sales | F7: =AVERAGE(Dataset!H:H) -> 182759.43 | G7: =MEDIAN(Dataset!H:H) -> 37980 | H7: =MIN(Dataset!H:H) -> 1799 | I7: =MAX(Dataset!H:H) -> 1207500 | J7: =_xlfn.STDEV.P(Dataset!H:H) -> 254080.6 | M7: Correlation Discount vs profits | N7: =CORREL(Dataset!I:I,Dataset!L:L) -> 0.38308688
E8: Discount | F8: =AVERAGE(Dataset!I:I) -> 13150.355 | G8: =MEDIAN(Dataset!I:I) -> 2585.25 | H8: =MIN(Dataset!I:I) -> 0 | I8: =MAX(Dataset!I:I) -> 149677.5 | J8: =_xlfn.STDEV.P(Dataset!I:I) -> 22946.521 | M8: Correlation Units vs Profit | N8: =CORREL(Dataset!E:E,Dataset!L:L) -> 0.22843691
E9: Sales | F9: =AVERAGE(Dataset!J:J) -> 169609.07 | G9: =MEDIAN(Dataset!J:J) -> 35540.2 | H9: =MIN(Dataset!J:J) -> 1655.08 | I9: =MAX(Dataset!J:J) -> 1159200 | J9: =_xlfn.STDEV.P(Dataset!J:J) -> 236557.2
E10: COGS | F10: =AVERAGE(Dataset!K:K) -> 145475.21 | G10: =MEDIAN(Dataset!K:K) -> 22506.25 | H10: =MIN(Dataset!K:K) -> 918 | I10: =MAX(Dataset!K:K) -> 950625 | J10: =_xlfn.STDEV.P(Dataset!K:K) -> 203719.84
E11: Profit | F11: =AVERAGE(Dataset!L:L) -> 24133.86 | G11: =MEDIAN(Dataset!L:L) -> 9242.2 | H11: =MIN(Dataset!L:L) -> -40617.5 | I11: =MAX(Dataset!L:L) -> 262200 | J11: =_xlfn.STDEV.P(Dataset!L:L) -> 42730.072
F13: Range of Units sold | G13: =I4-H4 -> 4292.5
E15: Unit sold IQR
E16: Quartile 1(25th Percentile) | F16: =_xlfn.QUARTILE.INC(Dataset!E2:E701,1) -> 905
E17: Quartile 3(27th Percentile) | F17: =_xlfn.QUARTILE.INC(Dataset!E2:E701,3) -> 2229.125
E18: IQR | F18: =F17-F16 -> 1324.125
E19: Lowest permissible value | F19: =F16-(1.5*F18) -> -1081.1875
E20: Highest permissible value | F20: =F17+1.5*F18 -> 4215.3125
B31: 3. SUMMARY OUTPUT- Regression Analysis | L31: 4. t-Test: Two-Sample Assuming Equal Variances
B33: Regression Statistics | M33: USA Sales | N33: Canada Sales
B34: Multiple R | C34: 0.86765142 | L34: Mean | M34: 21396.719 | N34: 25208.778
B35: R Square | C35: 0.75281899 | L35: Variance | M35: 1.4941914e+09 | N35: 1.7874275e+09
B36: Adjusted R Square | C36: 0.75210972 | L36: Observations | M36: 140 | N36: 140
B37: Standard Error | C37: 21289.909 | L37: Pooled Variance | M37: 1.6408094e+09
B38: Observations | C38: 700 | L38: Hypothesized Mean Difference | M38: 0
L39: df | M39: 278
B40: ANOVA | L40: t Stat | M40: -0.7873712
C41: df | D41: SS | E41: MS | F41: F | G41: Significance F | L41: P(T<=t) one-tail | M41: 0.21586768
B42: Regression | C42: 2 | D42: 9.6217897e+11 | E42: 4.8108949e+11 | F42: 1061.3979 | G42: 2.922565e-212 | L42: t Critical one-tail | M42: 1.6503532
B43: Residual | C43: 697 | D43: 3.1592239e+11 | E43: 4.5326024e+08 | L43: P(T<=t) two-tail | M43: 0.43173537
B44: Total | C44: 699 | D44: 1.2781014e+12 | L44: t Critical two-tail | M44: 1.968534
C46: Coefficients | D46: Standard Error | E46: t Stat | F46: P-value | G46: Lower 95% | H46: Upper 95% | I46: Lower 95.0% | J46: Upper 95.0%
B47: Intercept | C47: 282.15951 | D47: 991.31553 | E47: 0.28463138 | F47: 0.77601111 | G47: -1664.163 | H47: 2228.482 | I47: -1664.163 | J47: 2228.482
B48: X Variable 1 | C48: -0.89813993 | D48: 0.052434227 | E48: -17.128887 | F48: 3.7126899e-55 | G48: -1.0010879 | H48: -0.79519197 | I48: -1.0010879 | J48: -0.79519197
B49: X Variable 2 | C49: 0.21026328 | D49: 0.0050862249 | E49: 41.339753 | F49: 1.0986357e-189 | G49: 0.20027712 | H49: 0.22024944 | I49: 0.20027712 | J49: 0.22024944
C55: 5. Distribution Analysis Using Histogram

Sheet Graphical Analysis
D1: Graphical Analysis
B2: 1. Total Sales and Profit by Country
A3: Row Labels | B3: Sum of Profit | C3: Sum of Sales
A4: Canada | B4: 3529228.9 | C4: 24887655
A5: France | B5: 3781020.8 | C5: 24354172
A6: Germany | B6: 3680388.8 | C6: 23505341
A7: Mexico | B7: 2907523.1 | C7: 20949352
A8: United States of America | B8: 2995540.7 | C8: 25029830
A9: Grand Total | B9: 16893702 | C9: 1.1872635e+08
B14: 2. Total Units Sold by Segment
A15: Row Labels | B15: Sum of Units Sold | C15: Sum of Gross Sales
A16: Channel Partners | B16: 161263.5 | C16: 1935162
A17: Enterprise | B17: 168552 | C17: 21069000
A18: Government | B18: 470673.5 | C18: 56403066
A19: Midmarket | B19: 172178 | C19: 2582670
A20: Small Business | B20: 153139 | C20: 45941700
A21: Grand Total | B21: 1125806 | C21: 1.279316e+08
A36: 3. Sum of Sales and Profit by Product Category
A37: Row Labels | B37: Sum of Sale Price | C37: Sum of Profit
A38: Amarilla | B38: 12096 | C38: 2814104.1
A39: Carretera | B39: 10395 | C39: 1826804.9
A40: Montana | B40: 10890 | C40: 2114754.9
A41: Paseo | B41: 21852 | C41: 4797437.9
A42: Velo | B42: 12561 | C42: 2305992.5
A43: VTT | B43: 15106 | C43: 3034608
A44: Grand Total | B44: 82900 | C44: 16893702
A52: 4.Box plot to compare Profit distribution between USA and Canada
A77: 5. Units Sold vs Sales Scatter Plot | J77: 6. Profits vs Sales Scatter Plot
B100: 7. Heat Map
D105: Sales | E105: COGS | F105: Profit
C106: Sales | D106: 1
C107: COGS | D107: 0.99224377 | E107: 1
C108: Profit | D108: 0.80546219 | E108: 0.7255445 | F108: 1
A111: 8. Pivot table and chart sum of sales and profits by year
A112: Row Labels | B112: Sum of Profit | C112: Sum of Sales
A113: 2013 | B113: 3878464.5 | C113: 26415256
A114: September | B114: 763603.03 | C114: 4484000
A115: October | B115: 1657795.1 | C115: 9295611.1
A116: November | B116: 765502.3 | C116: 7267203.3
A117: December | B117: 691564.08 | C117: 5368441.1
...

Sheet Sactter plot data
A1: Units Sold | B1: Sales | C1: Profit
A2: 1618.5 | B2: 32370 | C2: 16185
A3: 1321 | B3: 26420 | C3: 13210
A4: 2178 | B4: 32670 | C4: 10890
A5: 888 | B5: 13320 | C5: 4440
A6: 2470 | B6: 37050 | C6: 12350
A7: 1513 | B7: 529550 | C7: 136170
A8: 921 | B8: 13815 | C8: 4605
A9: 2518 | B9: 30216 | C9: 22662
A10: 1899 | B10: 37980 | C10: 18990
A11: 1545 | B11: 18540 | C11: 13905
A12: 2470 | B12: 37050 | C12: 12350
A13: 2665.5 | B13: 333187.5 | C13: 13327.5
... A701: 1806 | B701: 18421.2 | C701: 13003.2

Sheet Histogram Bins
A1: Bin | B1: Frequency
A2: 1655.08 | B2: 1
A3: 2786.6 | B3: 10
A4: 3918.1199 | B4: 11
A5: 5049.6399 | B5: 21
A6: 6181.1598 | B6: 6
A7: 7312.6798 | B7: 13
A8: 8444.1998 | B8: 15
A9: 9575.7197 | B9: 18
A10: 10707.24 | B10: 24
A11: 11838.76 | B11: 8
A12: 12970.28 | B12: 13
A13: 14101.8 | B13: 11
... A1024: 1158068.5 | B1024: 0
A1025: More | B1025: 1

Sheet Heat Map Data
A1: Sales | B1: COGS | C1: Profit
A2: 32370 | B2: 16185 | C2: 16185
A3: 26420 | B3: 13210 | C3: 13210
A4: 32670 | B4: 21780 | C4: 10890
A5: 13320 | B5: 8880 | C5: 4440
A6: 37050 | B6: 24700 | C6: 12350
A7: 529550 | B7: 393380 | C7: 136170
A8: 13815 | B8: 9210 | C8: 4605
A9: 30216 | B9: 7554 | C9: 22662
A10: 37980 | B10: 18990 | C10: 18990
A11: 18540 | B11: 4635 | C11: 13905
A12: 37050 | B12: 24700 | C12: 12350
A13: 333187.5 | B13: 319860 | C13: 13327.5
... A701: 18421.2 | B701: 5418 | C701: 13003.2

Sheet Year wise sales & profits data
A1: Date | B1: Month Name | C1: Year | D1: Sales | E1: Profit
A2: 41640 | B2: January | C2: 2014 | D2: 32370 | E2: 16185
A3: 41640 | B3: January | C3: 2014 | D3: 26420 | E3: 13210
A4: 41791 | B4: June | C4: 2014 | D4: 32670 | E4: 10890
A5: 41791 | B5: June | C5: 2014 | D5: 13320 | E5: 4440
A6: 41791 | B6: June | C6: 2014 | D6: 37050 | E6: 12350
A7: 41974 | B7: December | C7: 2014 | D7: 529550 | E7: 136170
A8: 41699 | B8: March | C8: 2014 | D8: 13815 | E8: 4605
A9: 41791 | B9: June | C9: 2014 | D9: 30216 | E9: 22662
A10: 41791 | B10: June | C10: 2014 | D10: 37980 | E10: 18990
A11: 41791 | B11: June | C11: 2014 | D11: 18540 | E11: 13905
A12: 41791 | B12: June | C12: 2014 | D12: 37050 | E12: 12350
A13: 41821 | B13: July | C13: 2014 | D13: 333187.5 | E13: 13327.5
... A701: 41760 | B701: May | C701: 2014 | D701: 18421.2 | E701: 13003.2
